<!DOCTYPE html>
<html lang="en">
<head>
    <meta charset="UTF-8">
    <title>问题5</title>
</head>
<body>
<script>
  /*异常穿透
  *     -在链式调用的最后面指定失败的回调
  *     -链式调用过程中只要出现异常就会直接跳转到这个回调函数
  *
  * 中断Promise链
  *     -后续的回调函数不会被执行
  *     -方法：因为回调函数会根据Promise的状态进行调用，成功或者失败都会调用。
  *         所以，只要指定一个状态为等待态的Promise，后续的回调函数就不会执行，链就中断了。*/
  new Promise((resolve, reject) => {
      // resolve(1)
      reject(1)
  }).then(
      value => {
          console.log('onResolved1()', value)
          return 2
      },
      // reason => {throw reason}
  ).then(
      value => {
          console.log('onResolved2()', value)
          return 3
      },
      reason => {throw reason}
  ).then(
      value => {
          console.log('onResolved3()', value)
      },
      reason => Promise.reject(reason)
  ).catch(reason => {
      console.log('onReejected1()', reason)
      // throw reason
      // return Promise.reject(reason)
      return new Promise(() => {}) // 返回一个pending的promise  中断promise链
  }).then(
      value => {
          console.log('onResolved3()', value)
      },
      reason => {
          console.log('onReejected2()', reason)
      }
  )



</script>
</body>
</html>